[2024-06-18T13:50:27.346+0545] {local_task_job_runner.py:120} INFO - ::group::Pre task execution logs
[2024-06-18T13:50:27.361+0545] {taskinstance.py:2076} INFO - Dependencies all met for dep_context=non-requeueable deps ti=<TaskInstance: Backup_Database.send_mail scheduled__2024-06-18T07:50:00+00:00 [queued]>
[2024-06-18T13:50:27.366+0545] {taskinstance.py:2076} INFO - Dependencies all met for dep_context=requeueable deps ti=<TaskInstance: Backup_Database.send_mail scheduled__2024-06-18T07:50:00+00:00 [queued]>
[2024-06-18T13:50:27.367+0545] {taskinstance.py:2306} INFO - Starting attempt 2 of 2
[2024-06-18T13:50:27.380+0545] {taskinstance.py:2330} INFO - Executing <Task(EmailOperator): send_mail> on 2024-06-18 07:50:00+00:00
[2024-06-18T13:50:27.382+0545] {standard_task_runner.py:63} INFO - Started process 16526 to run task
[2024-06-18T13:50:27.386+0545] {standard_task_runner.py:90} INFO - Running: ['airflow', 'tasks', 'run', 'Backup_Database', 'send_mail', 'scheduled__2024-06-18T07:50:00+00:00', '--job-id', '5', '--raw', '--subdir', 'DAGS_FOLDER/backup.py', '--cfg-path', '/tmp/tmp3oi7_ztz']
[2024-06-18T13:50:27.387+0545] {standard_task_runner.py:91} INFO - Job 5: Subtask send_mail
[2024-06-18T13:50:27.426+0545] {task_command.py:426} INFO - Running <TaskInstance: Backup_Database.send_mail scheduled__2024-06-18T07:50:00+00:00 [running]> on host PRABAL-10.
[2024-06-18T13:50:27.484+0545] {taskinstance.py:2648} INFO - Exporting env vars: AIRFLOW_CTX_DAG_OWNER='prabal' AIRFLOW_CTX_DAG_ID='Backup_Database' AIRFLOW_CTX_TASK_ID='send_mail' AIRFLOW_CTX_EXECUTION_DATE='2024-06-18T07:50:00+00:00' AIRFLOW_CTX_TRY_NUMBER='2' AIRFLOW_CTX_DAG_RUN_ID='scheduled__2024-06-18T07:50:00+00:00'
[2024-06-18T13:50:27.485+0545] {taskinstance.py:430} INFO - ::endgroup::
[2024-06-18T13:50:27.496+0545] {logging_mixin.py:188} WARNING - /home/prabal/afenv/lib/python3.10/site-packages/airflow/utils/email.py:154 RemovedInAirflow3Warning: Fetching SMTP credentials from configuration variables will be deprecated in a future release. Please set credentials using a connection instead.
[2024-06-18T13:50:27.496+0545] {email.py:271} INFO - Email alerting: attempt 1
[2024-06-18T13:50:57.627+0545] {taskinstance.py:441} INFO - ::group::Post task execution logs
[2024-06-18T13:50:57.628+0545] {taskinstance.py:2905} ERROR - Task failed with exception
Traceback (most recent call last):
  File "/home/prabal/afenv/lib/python3.10/site-packages/airflow/models/taskinstance.py", line 465, in _execute_task
    result = _execute_callable(context=context, **execute_callable_kwargs)
  File "/home/prabal/afenv/lib/python3.10/site-packages/airflow/models/taskinstance.py", line 432, in _execute_callable
    return execute_callable(context=context, **execute_callable_kwargs)
  File "/home/prabal/afenv/lib/python3.10/site-packages/airflow/models/baseoperator.py", line 401, in wrapper
    return func(self, *args, **kwargs)
  File "/home/prabal/afenv/lib/python3.10/site-packages/airflow/operators/email.py", line 79, in execute
    send_email(
  File "/home/prabal/afenv/lib/python3.10/site-packages/airflow/utils/email.py", line 80, in send_email
    return backend(
  File "/home/prabal/afenv/lib/python3.10/site-packages/airflow/utils/email.py", line 154, in send_email_smtp
    send_mime_email(e_from=mail_from, e_to=recipients, mime_msg=msg, conn_id=conn_id, dryrun=dryrun)
  File "/home/prabal/afenv/lib/python3.10/site-packages/airflow/utils/email.py", line 273, in send_mime_email
    smtp_conn = _get_smtp_connection(smtp_host, smtp_port, smtp_timeout, smtp_ssl)
  File "/home/prabal/afenv/lib/python3.10/site-packages/airflow/utils/email.py", line 317, in _get_smtp_connection
    return smtplib.SMTP(host=host, port=port, timeout=timeout)
  File "/usr/lib/python3.10/smtplib.py", line 255, in __init__
    (code, msg) = self.connect(host, port)
  File "/usr/lib/python3.10/smtplib.py", line 341, in connect
    self.sock = self._get_socket(host, port, self.timeout)
  File "/usr/lib/python3.10/smtplib.py", line 312, in _get_socket
    return socket.create_connection((host, port), timeout,
  File "/usr/lib/python3.10/socket.py", line 845, in create_connection
    raise err
  File "/usr/lib/python3.10/socket.py", line 833, in create_connection
    sock.connect(sa)
OSError: [Errno 101] Network is unreachable
[2024-06-18T13:50:57.635+0545] {taskinstance.py:1206} INFO - Marking task as FAILED. dag_id=Backup_Database, task_id=send_mail, run_id=scheduled__2024-06-18T07:50:00+00:00, execution_date=20240618T075000, start_date=20240618T080527, end_date=20240618T080557
[2024-06-18T13:50:57.651+0545] {standard_task_runner.py:110} ERROR - Failed to execute job 5 for task send_mail ([Errno 101] Network is unreachable; 16526)
[2024-06-18T13:50:57.673+0545] {local_task_job_runner.py:240} INFO - Task exited with return code 1
[2024-06-18T13:50:57.682+0545] {taskinstance.py:3503} INFO - 0 downstream tasks scheduled from follow-on schedule check
[2024-06-18T13:50:57.683+0545] {local_task_job_runner.py:222} INFO - ::endgroup::
